<?xml version="1.0" ?>
<!-- =================================================================================== -->
<!-- |    This document was autogenerated by xacro from /home/ow-labs/ws_moveit/src/owl_description/urdf/owl_robot.xacro | -->
<!-- |    EDITING THIS FILE BY HAND IS NOT RECOMMENDED                                 | -->
<!-- =================================================================================== -->
<robot name="owl_d435">
    <!-- <xacro:include filename="$(find owl_description)/urdf/robotiq_v2.xacro" /> -->
    <link name="world" />
    <joint name="virtual_joint" type="fixed">
        <origin rpy="0 0 0" xyz="0 0 0.0" />
        <parent link="world" />
        <child link="base_link" />
    </joint>
    <link name="base_link">
        <inertial>
            <origin rpy="0 0 0" xyz="2.7395E-05 -0.01813 4.3722E-05" />
            <mass value="2.39" />
            <inertia ixx="0.0060063" ixy="-2.5541E-15" ixz="-2.5603E-07" iyy="0.0095451" iyz="5.1619E-15" izz="0.006006" />
        </inertial>
        <visual>
            <origin rpy="0 0 0" xyz="0 0 0" />
            <geometry>
                <mesh filename="package://owl_description/meshes/owl_robot/base_link.STL" />
            </geometry>
            <material name="">
                <color rgba="0.89804 0.91765 0.92941 1" />
            </material>
        </visual>
        <collision>
            <origin rpy="0 0 0" xyz="0 0 0" />
            <geometry>
                <mesh filename="package://owl_description/meshes/owl_robot/base_link.STL" />
            </geometry>
        </collision>
    </link>
    <link name="shoulder_link">
        <inertial>
            <origin rpy="0 0 0" xyz="0.00042134 0.034391 -0.10382" />
            <mass value="4.613" />
            <inertia ixx="0.0035279" ixy="-5.6452E-06" ixz="-9.4882E-07" iyy="0.0046955" iyz="0.00045199" izz="0.0048177" />
        </inertial>
        <visual>
            <origin rpy="0 0 0" xyz="0 0 0" />
            <geometry>
                <mesh filename="package://owl_description/meshes/owl_robot/shoulder_link.STL" />
            </geometry>
            <material name="">
                <color rgba="0.79216 0.81961 0.93333 1" />
            </material>
        </visual>
        <collision>
            <origin rpy="0 0 0" xyz="0 0 0" />
            <geometry>
                <mesh filename="package://owl_description/meshes/owl_robot/shoulder_link.STL" />
            </geometry>
        </collision>
    </link>
    <joint name="BJ" type="continuous">
        <origin rpy="-3.1416 0 -1.574" xyz="0 0 0" />
        <parent link="base_link" />
        <child link="shoulder_link" />
        <axis xyz="0 0 1" />
        <limit effort="500" lower="-2.0944" upper="2.0944" velocity="50" />
        <!-- <limit lower="-3.14" upper="3.14" /> -->
    </joint>
    <link name="link1">
        <inertial>
            <origin rpy="0 0 0" xyz=" 0.17795 0.00011012 -0.085428" />
            <mass value="9.431" />
            <inertia ixx="0.0052455" ixy="1.4977E-05" ixz="2.6778E-05" iyy="0.028778" iyz="-3.8624E-06" izz="0.032177" />
        </inertial>
        <visual>
            <origin rpy="0 0 0" xyz="0 0 0" />
            <geometry>
                <mesh filename="package://owl_description/meshes/owl_robot/link1.STL" />
            </geometry>
            <material name="">
                <color rgba="0.79216 0.81961 0.93333 1" />
            </material>
        </visual>
        <collision>
            <origin rpy="0 0 0" xyz="0 0 0" />
            <geometry>
                <mesh filename="package://owl_description/meshes/owl_robot/link1.STL" />
            </geometry>
        </collision>
    </link>
    <joint name="SJ" type="continuous">
        <origin rpy="0.58944 1.5675 -0.983" xyz="0.00018339 0.066603 -0.1405" />
        <parent link="shoulder_link" />
        <child link="link1" />
        <axis xyz="0.0027142 -0.0011243 1" />
        <limit effort="500" lower="-1.6" upper="1.6" velocity="50" />
        <!-- <limit lower="-2.355" upper="2.355" /> -->
    </joint>
    <link name="elbow_link">
        <inertial>
            <origin rpy="0 0 0" xyz="0.00023616 -0.028792 -0.029823" />
            <mass value="4.613" />
            <inertia ixx="0.0023499" ixy="-2.7675E-06" ixz="-4.1087E-07" iyy="0.0030181" iyz="-0.00026183" izz="0.0035661" />
        </inertial>
        <visual>
            <origin rpy="0 0 0" xyz="0 0 0" />
            <geometry>
                <mesh filename="package://owl_description/meshes/owl_robot/elbow_link.STL" />
            </geometry>
            <material name="">
                <color rgba="0.79216 0.81961 0.93333 1" />
            </material>
        </visual>
        <collision>
            <origin rpy="0 0 0" xyz="0 0 0" />
            <geometry>
                <mesh filename="package://owl_description/meshes/owl_robot/elbow_link.STL" />
            </geometry>
        </collision>
    </link>
    <joint name="EJ" type="continuous">
        <origin rpy="3.1389 -0.0018334 -1.5781" xyz="0.35575 0 -0.00096557" />
        <parent link="link1" />
        <child link="elbow_link" />
        <axis xyz="0 0 1" />
        <limit effort="500" lower="-1.57" upper="3.14" velocity="50" />
        <!-- <limit lower="-2.355" upper="2.355" /> -->
    </joint>
    <link name="link2">
        <inertial>
            <origin rpy="0 0 0" xyz="0.00015054 -0.075078 0.13834" />
            <mass value="2.4407" />
            <inertia ixx="0.009134" ixy="-3.9978E-06" ixz="-4.8015E-06" iyy="0.010823" iyz="0.00068065" izz="0.0041094" />
        </inertial>
        <visual>
            <origin rpy="0 0 0" xyz="0 0 0" />
            <geometry>
                <mesh filename="package://owl_description/meshes/owl_robot/link2.STL" />
            </geometry>
            <material name="">
                <color rgba="0.79216 0.81961 0.93333 1" />
            </material>
        </visual>
        <collision>
            <origin rpy="0 0 0" xyz="0 0 0" />
            <geometry>
                <mesh filename="package://owl_description/meshes/owl_robot/link2.STL" />
            </geometry>
        </collision>
    </link>
    <joint name="W1J" type="continuous">
        <origin rpy="1.5708 -0.0023608 0" xyz="0.00019567 -0.079361 -0.066603" />
        <parent link="elbow_link" />
        <child link="link2" />
        <axis xyz="0 0 -1" />
        <limit effort="500" lower="-2.84489" upper="2.84489" velocity="50" />
        <!-- <limit lower="-2.355" upper="2.355" /> -->
    </joint>
    <link name="w2w3_link">
        <inertial>
            <origin rpy="0 0 0" xyz="0.00025923 0.029764 0.027271" />
            <mass value="3.118" />
            <inertia ixx="0.0014884" ixy="2.1526E-06" ixz="6.6731E-06" iyy="0.0016882" iyz="0.0001816" izz="0.0019291" />
        </inertial>
        <visual>
            <origin rpy="0 0 0" xyz="0 0 0" />
            <geometry>
                <mesh filename="package://owl_description/meshes/owl_robot/w2w3_link.STL" />
            </geometry>
            <material name="">
                <color rgba="0.79216 0.81961 0.93333 1" />
            </material>
        </visual>
        <collision>
            <origin rpy="0 0 0" xyz="0 0 0" />
            <geometry>
                <mesh filename="package://owl_description/meshes/owl_robot/w2w3_link.STL" />
            </geometry>
        </collision>
    </link>
    <joint name="W2J" type="continuous">
        <origin rpy="2.745 -1.5667 -1.1726" xyz="0 0 0.27639" />
        <parent link="link2" />
        <child link="w2w3_link" />
        <axis xyz="0.0037507 -0.00083382 0.99999" />
        <limit effort="500" lower="-1.6" upper="2.1" velocity="50" />
        <!-- <limit lower="-2.355" upper="2.355" /> -->
    </joint>
    <link name="end_effector_link">
        <inertial>
            <origin rpy="0 0 0" xyz="2.2451E-05 -0.00060487 0.098537" />
            <mass value="0.188" />
            <inertia ixx="0.00017935" ixy="-3.2299E-08" ixz="-2.1374E-07" iyy="0.00017907" iyz="-4.545E-07" izz="0.00025742" />
        </inertial>
        <visual>
            <origin rpy="0 0 0" xyz="0 0 0" />
            <geometry>
                <mesh filename="package://owl_description/meshes/owl_robot/end_effector_link.STL" />
            </geometry>
            <material name="">
                <color rgba="0.79216 0.81961 0.93333 1" />
            </material>
        </visual>
        <collision>
            <origin rpy="0 0 0" xyz="0 0 0" />
            <geometry>
                <mesh filename="package://owl_description/meshes/owl_robot/end_effector_link.STL" />
            </geometry>
        </collision>
    </link>
    <joint name="W3J" type="continuous">
        <origin rpy="-1.2578 -1.5668 -0.31786" xyz="0 0 0" />
        <limit effort="500" lower="-3.1" upper="3.1" velocity="50" />
        <parent link="w2w3_link" />
        <child link="end_effector_link" />
        <axis xyz="0 0 1" />
    </joint>
    <link name="tcp">
        <inertial>
            <origin rpy="0 0 0" xyz="0 0 0" />
            <mass value="1e-9" />
            <inertia ixx="0" ixy="0" ixz="0" iyy="0" iyz="0" izz="0" />
        </inertial>
    </link>
    <joint name="tcp_frame" type="fixed">
        <origin rpy="5.94633e-15 -1.33504e-14 -1.5708" xyz="4.33681e-19 0 0.1225" />
        <parent link="end_effector_link" />
        <child link="tcp" />
        <axis xyz="0 0 0" />
    </joint>
    <link name="camera_holder">
        <visual>
            <origin rpy="0 0 0" xyz="0 0 0" />
            <geometry>
                <mesh filename="package://owl_description/meshes/holder/MOUNT.STL" scale="0.001 0.001 0.001" />
            </geometry>
            <material name="">
                <color rgba="0.79216 0.81961 0.93333 1" />
            </material>
        </visual>
        <collision>
            <origin rpy="0 0 0" xyz="0 0 0" />
            <geometry>
                <mesh filename="package://owl_description/meshes/holder/MOUNT.STL" scale="0.001 0.001 0.001" />
            </geometry>
        </collision>
        <inertial>
            <mass value="0.1" />
            <origin xyz="0 0 0" rpy="0 0 0" />
            <inertia ixx="0.03" iyy="0.03" izz="0.03" ixy="0.0" ixz="0.0" iyz="0.0" />
        </inertial>
    </link>
    <joint name="camera_holder_joint" type="fixed">
        <origin rpy="1.57 0 3.14" xyz="0.045 -0.045 -0.053" />
        <parent link="tcp" />
        <child link="camera_holder" />
        <axis xyz="0 0 0" />
    </joint>
    <link name="gripper_model">
        <visual>
            <origin rpy="0 0 0" xyz="0 0 0" />
            <geometry>
                <mesh filename="package://owl_description/meshes/holder/ANG_GRIPPER.STL" scale="0.001 0.001 0.001" />
            </geometry>
            <material name="">
                <color rgba="0.79216 0.81961 0.93333 1" />
            </material>
        </visual>
        <collision>
            <origin rpy="0 0 0" xyz="0 0 0" />
            <geometry>
                <mesh filename="package://owl_description/meshes/holder/ANG_GRIPPER.STL" scale="0.001 0.001 0.001" />
            </geometry>
        </collision>
        <inertial>
            <mass value="0.1" />
            <origin xyz="0 0 0" rpy="0 0 0" />
            <inertia ixx="0.03" iyy="0.03" izz="0.03" ixy="0.0" ixz="0.0" iyz="0.0" />
        </inertial>
    </link>
    <joint name="gripper_holder_joint" type="fixed">
        <origin rpy="0 3.14 0" xyz="0.35 0.028 0.092" />
        <parent link="camera_holder" />
        <child link="gripper_model" />
        <axis xyz="1.57 1.57 0" />
    </joint>
    <gazebo>
        <plugin filename="libgazebo_ros_control.so" name="gazebo_ros_control">
            <!-- <robotNamespace>/owr_6.3</robotNamespace> -->
            <!-- <robotSimType>gazebo_ros_control/DefaultRobotHWSim</robotSimType> -->
            <robotNamespace>/</robotNamespace>
        </plugin>
    </gazebo>
    <gazebo>
        <plugin filename="libgazebo_ros_joint_state_publisher.so" name="joint_state_publisher">
            <jointName>BJ, SJ, EJ, W1J, W2J, W3J</jointName>
        </plugin>
    </gazebo>
    <gazebo reference="shoulder_link">
        <material>Gazebo/Gray</material>
        <selfCollide>true</selfCollide>
    </gazebo>
    <gazebo reference="link1">
        <material>Gazebo/Gray</material>
        <selfCollide>true</selfCollide>
    </gazebo>
    <gazebo reference="elbow_link">
        <material>Gazebo/Gray</material>
        <selfCollide>true</selfCollide>
    </gazebo>
    <gazebo reference="link2">
        <material>Gazebo/Gray</material>
        <selfCollide>true</selfCollide>
    </gazebo>
    <gazebo reference="w2w3_link">
        <material>Gazebo/Gray</material>
        <selfCollide>true</selfCollide>
    </gazebo>
    <gazebo reference="end_effector_link">
        <material>Gazebo/Gray</material>
        <selfCollide>true</selfCollide>
    </gazebo>
    <gazebo reference="tcp">
        <material>Gazebo/Gray</material>
        <selfCollide>true</selfCollide>
    </gazebo>
    <transmission name="BJ_trans">
        <type>transmission_interface/SimpleTransmission</type>
        <joint name="BJ">
            <hardwareInterface>hardware_interface/PositionJointInterface</hardwareInterface>
        </joint>
        <actuator name="BJ_motor">
            <hardwareInterface>hardware_interface/PositionJointInterface</hardwareInterface>
            <mechanicalReduction>1</mechanicalReduction>
        </actuator>
    </transmission>
    <transmission name="SJ_trans">
        <type>transmission_interface/SimpleTransmission</type>
        <joint name="SJ">
            <hardwareInterface>hardware_interface/PositionJointInterface</hardwareInterface>
        </joint>
        <actuator name="SJ_motor">
            <hardwareInterface>hardware_interface/PositionJointInterface</hardwareInterface>
            <mechanicalReduction>1</mechanicalReduction>
        </actuator>
    </transmission>
    <transmission name="EJ_trans">
        <type>transmission_interface/SimpleTransmission</type>
        <joint name="EJ">
            <hardwareInterface>hardware_interface/PositionJointInterface</hardwareInterface>
        </joint>
        <actuator name="EJ_motor">
            <hardwareInterface>hardware_interface/PositionJointInterface</hardwareInterface>
            <mechanicalReduction>1</mechanicalReduction>
        </actuator>
    </transmission>
    <transmission name="W1J_trans">
        <type>transmission_interface/SimpleTransmission</type>
        <joint name="W1J">
            <hardwareInterface>hardware_interface/PositionJointInterface</hardwareInterface>
        </joint>
        <actuator name="W1J_motor">
            <hardwareInterface>hardware_interface/PositionJointInterface</hardwareInterface>
            <mechanicalReduction>1</mechanicalReduction>
        </actuator>
    </transmission>
    <transmission name="W2J_trans">
        <type>transmission_interface/SimpleTransmission</type>
        <joint name="W2J">
            <hardwareInterface>hardware_interface/PositionJointInterface</hardwareInterface>
        </joint>
        <actuator name="W2J_motor">
            <hardwareInterface>hardware_interface/PositionJointInterface</hardwareInterface>
            <mechanicalReduction>1</mechanicalReduction>
        </actuator>
    </transmission>
    <transmission name="W3J_trans">
        <type>transmission_interface/SimpleTransmission</type>
        <joint name="W3J">
            <hardwareInterface>hardware_interface/PositionJointInterface</hardwareInterface>
        </joint>
        <actuator name="W3J_motor">
            <hardwareInterface>hardware_interface/PositionJointInterface</hardwareInterface>
            <mechanicalReduction>1</mechanicalReduction>
        </actuator>
    </transmission>
    <!-- <xacro:robotiq_gripper /> -->
    <!-- <joint name="robot_ee-gripper_robotiq_arg2f_base_joint" type="fixed">
        <origin xyz="0 0 -0.105" rpy="3.14 0 0" />
        <parent link="tcp" />
        <child link="robotiq_coupler_link" />
    </joint> -->
    <material name="camera_aluminum">
        <color rgba="0.5 0.5 0.5 1" />
    </material>
    <!-- camera body, with origin at bottom screw mount -->
    <joint name="camera_joint" type="fixed">
        <origin rpy="1.57 0 0" xyz="0.1315 0.0235 0.041" />
        <parent link="camera_holder" />
        <child link="camera_bottom_screw_frame" />
    </joint>
    <link name="camera_bottom_screw_frame" />
    <joint name="camera_link_joint" type="fixed">
        <origin rpy="0 0 0" xyz="0 0.0175 0.0125" />
        <parent link="camera_bottom_screw_frame" />
        <child link="camera_link" />
    </joint>
    <link name="camera_link">
        <visual>
            <origin rpy="1.5707963267948966 0 1.5707963267948966" xyz="0.0149 -0.0175 0" />
            <geometry>
                <!-- <box size="${d435_cam_width} ${d435_cam_height} ${d435_cam_depth}"/> -->
                <mesh filename="package://owl_description/meshes/d435/d435.dae" />
            </geometry>
            <material name="camera_aluminum" />
        </visual>
        <collision>
            <origin rpy="0 0 0" xyz="0 -0.0175 0" />
            <geometry>
                <box size="0.02505 0.09 0.025" />
            </geometry>
        </collision>
        <inertial>
            <!-- The following are not reliable values, and should not be used for modeling -->
            <mass value="0.564" />
            <origin xyz="0 0 0" rpy="0 0 0" />
            <inertia ixx="0.003881243" ixy="0.0" ixz="0.0" iyy="0.000498940" iyz="0.0" izz="0.003879257" />
        </inertial>
    </link>
    <!-- camera depth joints and links -->
    <joint name="camera_depth_joint" type="fixed">
        <origin rpy="0 0 0" xyz="0 0 0" />
        <parent link="camera_link" />
        <child link="camera_depth_frame" />
    </joint>
    <link name="camera_depth_frame" />
    <joint name="camera_depth_optical_joint" type="fixed">
        <origin rpy="-1.5707963267948966 0 -1.5707963267948966" xyz="0 0 0" />
        <parent link="camera_depth_frame" />
        <child link="camera_depth_optical_frame" />
    </joint>
    <link name="camera_depth_optical_frame" />
    <!-- camera left IR joints and links -->
    <joint name="camera_left_ir_joint" type="fixed">
        <origin rpy="0 0 0" xyz="0 0.0 0" />
        <parent link="camera_depth_frame" />
        <child link="camera_left_ir_frame" />
    </joint>
    <link name="camera_left_ir_frame" />
    <joint name="camera_left_ir_optical_joint" type="fixed">
        <origin rpy="-1.5707963267948966 0 -1.5707963267948966" xyz="0 0 0" />
        <parent link="camera_left_ir_frame" />
        <child link="camera_left_ir_optical_frame" />
    </joint>
    <link name="camera_left_ir_optical_frame" />
    <!-- camera right IR joints and links -->
    <joint name="camera_right_ir_joint" type="fixed">
        <origin rpy="0 0 0" xyz="0 -0.05 0" />
        <parent link="camera_depth_frame" />
        <child link="camera_right_ir_frame" />
    </joint>
    <link name="camera_right_ir_frame" />
    <joint name="camera_right_ir_optical_joint" type="fixed">
        <origin rpy="-1.5707963267948966 0 -1.5707963267948966" xyz="0 0 0" />
        <parent link="camera_right_ir_frame" />
        <child link="camera_right_ir_optical_frame" />
    </joint>
    <link name="camera_right_ir_optical_frame" />
    <!-- camera color joints and links -->
    <joint name="camera_color_joint" type="fixed">
        <origin rpy="0 0 0" xyz="0 0.015 0" />
        <parent link="camera_depth_frame" />
        <child link="camera_color_frame" />
    </joint>
    <link name="camera_color_frame" />
    <joint name="camera_color_optical_joint" type="fixed">
        <origin rpy="-1.5707963267948966 0 -1.5707963267948966" xyz="0 0 0" />
        <parent link="camera_color_frame" />
        <child link="camera_color_optical_frame" />
    </joint>
    <link name="camera_color_optical_frame" />
    <gazebo reference="camera_link">
        <self_collide>0</self_collide>
        <enable_wind>0</enable_wind>
        <kinematic>0</kinematic>
        <!-- <gravity>1</gravity> -->
        <!--<mu>1</mu>-->
        <mu2>1</mu2>
        <fdir1>0 0 0</fdir1>
        <!--<slip1>0</slip1>
      <slip2>0</slip2>-->
        <kp>1e+13</kp>
        <kd>1</kd>
        <!--<max_vel>0.01</max_vel>
      <min_depth>0</min_depth>-->
        <sensor name="cameracolor" type="camera">
            <camera name="camera">
                <horizontal_fov>1.2112585008840648</horizontal_fov>
                <image>
                    <width>640</width>
                    <height>480</height>
                    <format>RGB_INT8</format>
                </image>
                <clip>
                    <near>0.1</near>
                    <far>100</far>
                </clip>
                <noise>
                    <type>gaussian</type>
                    <mean>0.0</mean>
                    <stddev>0.007</stddev>
                </noise>
            </camera>
            <always_on>1</always_on>
            <update_rate>30</update_rate>
            <visualize>1</visualize>
        </sensor>
        <sensor name="cameraired1" type="camera">
            <camera name="camera">
                <horizontal_fov>1.4870205226991688</horizontal_fov>
                <image>
                    <width>1280</width>
                    <height>720</height>
                    <format>L_INT8</format>
                </image>
                <clip>
                    <near>0.1</near>
                    <far>100</far>
                </clip>
                <noise>
                    <type>gaussian</type>
                    <mean>0.0</mean>
                    <stddev>0.05</stddev>
                </noise>
            </camera>
            <always_on>1</always_on>
            <update_rate>90</update_rate>
            <visualize>0</visualize>
        </sensor>
        <sensor name="cameraired2" type="camera">
            <camera name="camera">
                <horizontal_fov>1.4870205226991688</horizontal_fov>
                <image>
                    <width>1280</width>
                    <height>720</height>
                    <format>L_INT8</format>
                </image>
                <clip>
                    <near>0.1</near>
                    <far>100</far>
                </clip>
                <noise>
                    <type>gaussian</type>
                    <mean>0.0</mean>
                    <stddev>0.05</stddev>
                </noise>
            </camera>
            <always_on>1</always_on>
            <update_rate>90</update_rate>
            <visualize>0</visualize>
        </sensor>
        <sensor name="cameradepth" type="depth">
            <camera name="camera">
                <horizontal_fov>1.4870205226991688</horizontal_fov>
                <image>
                    <width>1280</width>
                    <height>720</height>
                </image>
                <clip>
                    <near>0.1</near>
                    <far>100</far>
                </clip>
                <noise>
                    <type>gaussian</type>
                    <mean>0.0</mean>
                    <stddev>0.100</stddev>
                </noise>
            </camera>
            <always_on>1</always_on>
            <update_rate>90</update_rate>
            <visualize>0</visualize>
        </sensor>
    </gazebo>
    <gazebo>
        <plugin filename="librealsense_gazebo_plugin.so" name="camera">
            <prefix>camera</prefix>
            <depthUpdateRate>30.0</depthUpdateRate>
            <colorUpdateRate>30.0</colorUpdateRate>
            <infraredUpdateRate>30.0</infraredUpdateRate>
            <depthTopicName>depth/image_raw</depthTopicName>
            <depthCameraInfoTopicName>depth/camera_info</depthCameraInfoTopicName>
            <colorTopicName>color/image_raw</colorTopicName>
            <colorCameraInfoTopicName>color/camera_info</colorCameraInfoTopicName>
            <infrared1TopicName>infra1/image_raw</infrared1TopicName>
            <infrared1CameraInfoTopicName>infra1/camera_info</infrared1CameraInfoTopicName>
            <infrared2TopicName>infra2/image_raw</infrared2TopicName>
            <infrared2CameraInfoTopicName>infra2/camera_info</infrared2CameraInfoTopicName>
            <colorOpticalframeName>camera_color_optical_frame</colorOpticalframeName>
            <depthOpticalframeName>camera_depth_optical_frame</depthOpticalframeName>
            <infrared1OpticalframeName>camera_left_ir_optical_frame</infrared1OpticalframeName>
            <infrared2OpticalframeName>camera_right_ir_optical_frame</infrared2OpticalframeName>
            <rangeMinDepth>0.2</rangeMinDepth>
            <rangeMaxDepth>1.0</rangeMaxDepth>
            <pointCloud>True</pointCloud>
            <pointCloudTopicName>depth/color/points</pointCloudTopicName>
            <pointCloudCutoff>0.25</pointCloudCutoff>
            <pointCloudCutoffMax>1.5</pointCloudCutoffMax>
        </plugin>
    </gazebo>
    <gazebo reference="camera_bottom_screw_frame">
        <turnGravityOff>true</turnGravityOff>
    </gazebo>
    <gazebo reference="camera_link">
        <turnGravityOff>true</turnGravityOff>
    </gazebo>
    <gazebo reference="camera_depth_frame">
        <turnGravityOff>true</turnGravityOff>
    </gazebo>
    <gazebo reference="camera_depth_optical_frame">
        <turnGravityOff>true</turnGravityOff>
    </gazebo>
    <gazebo reference="camera_left_ir_frame">
        <turnGravityOff>true</turnGravityOff>
    </gazebo>
    <gazebo reference="camera_left_ir_optical_frame">
        <turnGravityOff>true</turnGravityOff>
    </gazebo>
    <gazebo reference="camera_right_ir_frame">
        <turnGravityOff>true</turnGravityOff>
    </gazebo>
    <gazebo reference="camera_right_ir_optical_frame">
        <turnGravityOff>true</turnGravityOff>
    </gazebo>
    <gazebo reference="camera_color_frame">
        <turnGravityOff>true</turnGravityOff>
    </gazebo>
    <gazebo reference="camera_color_optical_frame">
        <turnGravityOff>true</turnGravityOff>
    </gazebo>
</robot>

