<sdf version='1.7'>
  <model name='owl_d435'>
    <joint name='virtual_joint' type='fixed'>
      <pose relative_to='__model__'>0 0 0 0 -0 0</pose>
      <parent>world</parent>
      <child>base_link</child>
    </joint>
    <link name='base_link'>
      <pose relative_to='virtual_joint'>0 0 0 0 -0 0</pose>
      <inertial>
        <pose>2.7e-05 -0.01813 4.4e-05 0 -0 0</pose>
        <mass>2.39</mass>
        <inertia>
          <ixx>0.0060063</ixx>
          <ixy>-2.5541e-15</ixy>
          <ixz>-2.5603e-07</ixz>
          <iyy>0.0095451</iyy>
          <iyz>5.1619e-15</iyz>
          <izz>0.006006</izz>
        </inertia>
      </inertial>
      <collision name='base_link_collision'>
        <pose>0 0 0 0 -0 0</pose>
        <geometry>
          <mesh>
            <scale>1 1 1</scale>
            <uri>model://owl_description/meshes/owl_robot/base_link.STL</uri>
          </mesh>
        </geometry>
      </collision>
      <visual name='base_link_visual'>
        <pose>0 0 0 0 -0 0</pose>
        <geometry>
          <mesh>
            <scale>1 1 1</scale>
            <uri>model://owl_description/meshes/owl_robot/base_link.STL</uri>
          </mesh>
        </geometry>
      </visual>
    </link>
    <joint name='BJ' type='revolute'>
      <pose relative_to='base_link'>0 0 0 3.14159 0 -1.574</pose>
      <parent>base_link</parent>
      <child>shoulder_link</child>
      <axis>
        <xyz>0 0 1</xyz>
        <limit>
          <effort>500</effort>
          <velocity>50</velocity>
          <lower>-1e+16</lower>
          <upper>1e+16</upper>
        </limit>
        <dynamics>
          <spring_reference>0</spring_reference>
          <spring_stiffness>0</spring_stiffness>
        </dynamics>
      </axis>
    </joint>
    <link name='shoulder_link'>
      <pose relative_to='BJ'>0 0 0 0 -0 0</pose>
      <inertial>
        <pose>0.000421 0.034391 -0.10382 0 -0 0</pose>
        <mass>4.613</mass>
        <inertia>
          <ixx>0.0035279</ixx>
          <ixy>-5.6452e-06</ixy>
          <ixz>-9.4882e-07</ixz>
          <iyy>0.0046955</iyy>
          <iyz>0.00045199</iyz>
          <izz>0.0048177</izz>
        </inertia>
      </inertial>
      <collision name='shoulder_link_collision'>
        <pose>0 0 0 0 -0 0</pose>
        <geometry>
          <mesh>
            <scale>1 1 1</scale>
            <uri>model://owl_description/meshes/owl_robot/shoulder_link.STL</uri>
          </mesh>
        </geometry>
        <surface>
          <contact>
            <ode/>
          </contact>
          <friction>
            <ode/>
          </friction>
        </surface>
      </collision>
      <visual name='shoulder_link_visual'>
        <pose>0 0 0 0 -0 0</pose>
        <geometry>
          <mesh>
            <scale>1 1 1</scale>
            <uri>model://owl_description/meshes/owl_robot/shoulder_link.STL</uri>
          </mesh>
        </geometry>
        <material>
          <script>
            <name>Gazebo/Gray</name>
            <uri>file://media/materials/scripts/gazebo.material</uri>
          </script>
        </material>
      </visual>
      <self_collide>1</self_collide>
    </link>
    <joint name='SJ' type='revolute'>
      <pose relative_to='shoulder_link'>0.000183 0.066603 -0.1405 0.58944 1.5675 -0.983</pose>
      <parent>shoulder_link</parent>
      <child>link1</child>
      <axis>
        <xyz>0.002714 -0.001124 1</xyz>
        <limit>
          <effort>500</effort>
          <velocity>50</velocity>
          <lower>-1e+16</lower>
          <upper>1e+16</upper>
        </limit>
        <dynamics>
          <spring_reference>0</spring_reference>
          <spring_stiffness>0</spring_stiffness>
        </dynamics>
      </axis>
    </joint>
    <link name='link1'>
      <pose relative_to='SJ'>0 0 0 0 -0 0</pose>
      <inertial>
        <pose>0.17795 0.00011 -0.085428 0 -0 0</pose>
        <mass>9.431</mass>
        <inertia>
          <ixx>0.0052455</ixx>
          <ixy>1.4977e-05</ixy>
          <ixz>2.6778e-05</ixz>
          <iyy>0.028778</iyy>
          <iyz>-3.8624e-06</iyz>
          <izz>0.032177</izz>
        </inertia>
      </inertial>
      <collision name='link1_collision'>
        <pose>0 0 0 0 -0 0</pose>
        <geometry>
          <mesh>
            <scale>1 1 1</scale>
            <uri>model://owl_description/meshes/owl_robot/link1.STL</uri>
          </mesh>
        </geometry>
        <surface>
          <contact>
            <ode/>
          </contact>
          <friction>
            <ode/>
          </friction>
        </surface>
      </collision>
      <visual name='link1_visual'>
        <pose>0 0 0 0 -0 0</pose>
        <geometry>
          <mesh>
            <scale>1 1 1</scale>
            <uri>model://owl_description/meshes/owl_robot/link1.STL</uri>
          </mesh>
        </geometry>
        <material>
          <script>
            <name>Gazebo/Gray</name>
            <uri>file://media/materials/scripts/gazebo.material</uri>
          </script>
        </material>
      </visual>
      <self_collide>1</self_collide>
    </link>
    <joint name='EJ' type='revolute'>
      <pose relative_to='link1'>0.35575 0 -0.000966 3.1389 -0.001833 -1.5781</pose>
      <parent>link1</parent>
      <child>elbow_link</child>
      <axis>
        <xyz>0 0 1</xyz>
        <limit>
          <effort>500</effort>
          <velocity>50</velocity>
          <lower>-1e+16</lower>
          <upper>1e+16</upper>
        </limit>
        <dynamics>
          <spring_reference>0</spring_reference>
          <spring_stiffness>0</spring_stiffness>
        </dynamics>
      </axis>
    </joint>
    <link name='elbow_link'>
      <pose relative_to='EJ'>0 0 0 0 -0 0</pose>
      <inertial>
        <pose>0.000236 -0.028792 -0.029823 0 -0 0</pose>
        <mass>4.613</mass>
        <inertia>
          <ixx>0.0023499</ixx>
          <ixy>-2.7675e-06</ixy>
          <ixz>-4.1087e-07</ixz>
          <iyy>0.0030181</iyy>
          <iyz>-0.00026183</iyz>
          <izz>0.0035661</izz>
        </inertia>
      </inertial>
      <collision name='elbow_link_collision'>
        <pose>0 0 0 0 -0 0</pose>
        <geometry>
          <mesh>
            <scale>1 1 1</scale>
            <uri>model://owl_description/meshes/owl_robot/elbow_link.STL</uri>
          </mesh>
        </geometry>
        <surface>
          <contact>
            <ode/>
          </contact>
          <friction>
            <ode/>
          </friction>
        </surface>
      </collision>
      <visual name='elbow_link_visual'>
        <pose>0 0 0 0 -0 0</pose>
        <geometry>
          <mesh>
            <scale>1 1 1</scale>
            <uri>model://owl_description/meshes/owl_robot/elbow_link.STL</uri>
          </mesh>
        </geometry>
        <material>
          <script>
            <name>Gazebo/Gray</name>
            <uri>file://media/materials/scripts/gazebo.material</uri>
          </script>
        </material>
      </visual>
      <self_collide>1</self_collide>
    </link>
    <joint name='W1J' type='revolute'>
      <pose relative_to='elbow_link'>0.000196 -0.079361 -0.066603 1.5708 -0.002361 -0</pose>
      <parent>elbow_link</parent>
      <child>link2</child>
      <axis>
        <xyz>0 0 -1</xyz>
        <limit>
          <effort>500</effort>
          <velocity>50</velocity>
          <lower>-1e+16</lower>
          <upper>1e+16</upper>
        </limit>
        <dynamics>
          <spring_reference>0</spring_reference>
          <spring_stiffness>0</spring_stiffness>
        </dynamics>
      </axis>
    </joint>
    <link name='link2'>
      <pose relative_to='W1J'>0 0 0 0 -0 0</pose>
      <inertial>
        <pose>0.000151 -0.075078 0.13834 0 -0 0</pose>
        <mass>2.4407</mass>
        <inertia>
          <ixx>0.009134</ixx>
          <ixy>-3.9978e-06</ixy>
          <ixz>-4.8015e-06</ixz>
          <iyy>0.010823</iyy>
          <iyz>0.00068065</iyz>
          <izz>0.0041094</izz>
        </inertia>
      </inertial>
      <collision name='link2_collision'>
        <pose>0 0 0 0 -0 0</pose>
        <geometry>
          <mesh>
            <scale>1 1 1</scale>
            <uri>model://owl_description/meshes/owl_robot/link2.STL</uri>
          </mesh>
        </geometry>
        <surface>
          <contact>
            <ode/>
          </contact>
          <friction>
            <ode/>
          </friction>
        </surface>
      </collision>
      <visual name='link2_visual'>
        <pose>0 0 0 0 -0 0</pose>
        <geometry>
          <mesh>
            <scale>1 1 1</scale>
            <uri>model://owl_description/meshes/owl_robot/link2.STL</uri>
          </mesh>
        </geometry>
        <material>
          <script>
            <name>Gazebo/Gray</name>
            <uri>file://media/materials/scripts/gazebo.material</uri>
          </script>
        </material>
      </visual>
      <self_collide>1</self_collide>
    </link>
    <joint name='W2J' type='revolute'>
      <pose relative_to='link2'>0 0 0.27639 2.745 -1.5667 -1.1726</pose>
      <parent>link2</parent>
      <child>w2w3_link</child>
      <axis>
        <xyz>0.003751 -0.000834 0.99999</xyz>
        <limit>
          <effort>500</effort>
          <velocity>50</velocity>
          <lower>-1e+16</lower>
          <upper>1e+16</upper>
        </limit>
        <dynamics>
          <spring_reference>0</spring_reference>
          <spring_stiffness>0</spring_stiffness>
        </dynamics>
      </axis>
    </joint>
    <link name='w2w3_link'>
      <pose relative_to='W2J'>0 0 0 0 -0 0</pose>
      <inertial>
        <pose>0.000259 0.029764 0.027271 0 -0 0</pose>
        <mass>3.118</mass>
        <inertia>
          <ixx>0.0014884</ixx>
          <ixy>2.1526e-06</ixy>
          <ixz>6.6731e-06</ixz>
          <iyy>0.0016882</iyy>
          <iyz>0.0001816</iyz>
          <izz>0.0019291</izz>
        </inertia>
      </inertial>
      <collision name='w2w3_link_collision'>
        <pose>0 0 0 0 -0 0</pose>
        <geometry>
          <mesh>
            <scale>1 1 1</scale>
            <uri>model://owl_description/meshes/owl_robot/w2w3_link.STL</uri>
          </mesh>
        </geometry>
        <surface>
          <contact>
            <ode/>
          </contact>
          <friction>
            <ode/>
          </friction>
        </surface>
      </collision>
      <visual name='w2w3_link_visual'>
        <pose>0 0 0 0 -0 0</pose>
        <geometry>
          <mesh>
            <scale>1 1 1</scale>
            <uri>model://owl_description/meshes/owl_robot/w2w3_link.STL</uri>
          </mesh>
        </geometry>
        <material>
          <script>
            <name>Gazebo/Gray</name>
            <uri>file://media/materials/scripts/gazebo.material</uri>
          </script>
        </material>
      </visual>
      <self_collide>1</self_collide>
    </link>
    <joint name='W3J' type='revolute'>
      <pose relative_to='w2w3_link'>0 0 0 -1.2578 -1.5668 -0.31786</pose>
      <parent>w2w3_link</parent>
      <child>end_effector_link</child>
      <axis>
        <xyz>0 0 1</xyz>
        <limit>
          <effort>500</effort>
          <velocity>50</velocity>
          <lower>-1e+16</lower>
          <upper>1e+16</upper>
        </limit>
        <dynamics>
          <spring_reference>0</spring_reference>
          <spring_stiffness>0</spring_stiffness>
        </dynamics>
      </axis>
    </joint>
    <link name='end_effector_link'>
      <pose relative_to='W3J'>0 0 0 0 -0 0</pose>
      <inertial>
        <pose>0.037495 0.008481 0.127359 0 -0 0</pose>
        <mass>0.97852</mass>
        <inertia>
          <ixx>0.00455084</ixx>
          <ixy>-0.000238701</ixy>
          <ixz>-7.86275e-05</ixz>
          <iyy>0.00210393</iyy>
          <iyz>-2.17245e-05</iyz>
          <izz>0.00533913</izz>
        </inertia>
      </inertial>
      <collision name='end_effector_link_collision'>
        <pose>0 0 0 0 -0 0</pose>
        <geometry>
          <mesh>
            <scale>1 1 1</scale>
            <uri>model://owl_description/meshes/owl_robot/end_effector_link.STL</uri>
          </mesh>
        </geometry>
        <surface>
          <contact>
            <ode/>
          </contact>
          <friction>
            <ode/>
          </friction>
        </surface>
      </collision>
      <collision name='end_effector_link_fixed_joint_lump__camera_holder_collision_1'>
        <pose>-0.0425 -0.0425 0.1095 -0 -0 -0.0008</pose>
        <geometry>
          <mesh>
            <scale>0.001 0.001 0.001</scale>
            <uri>model://owl_description/meshes/holder/Camera_Ur5e_gripper_Mount_Disc.STL</uri>
          </mesh>
        </geometry>
      </collision>
      <collision name='end_effector_link_fixed_joint_lump__camera_link_collision_2'>
        <pose>0.065032 -0.002586 0.12951 -0.0008 -1.5708 0</pose>
        <geometry>
          <box>
            <size>0.02505 0.09 0.025</size>
          </box>
        </geometry>
        <surface>
          <contact>
            <ode>
              <kp>1e+13</kp>
              <kd>1</kd>
            </ode>
          </contact>
          <friction>
            <ode>
              <mu2>1</mu2>
              <fdir1>0 0 0</fdir1>
            </ode>
          </friction>
        </surface>
      </collision>
      <collision name='end_effector_link_fixed_joint_lump__gripper_robotiq_arg2f_base_link_collision_3'>
        <pose>0 -0 0.1145 0 -0 3.14159</pose>
        <geometry>
          <mesh>
            <scale>1 1 1</scale>
            <uri>model://robotiq_2f_85_gripper_visualization/meshes/collision/robotiq_arg2f_base_link.stl</uri>
          </mesh>
        </geometry>
      </collision>
      <visual name='end_effector_link_visual'>
        <pose>0 0 0 0 -0 0</pose>
        <geometry>
          <mesh>
            <scale>1 1 1</scale>
            <uri>model://owl_description/meshes/owl_robot/end_effector_link.STL</uri>
          </mesh>
        </geometry>
        <material>
          <script>
            <name>Gazebo/Gray</name>
            <uri>file://media/materials/scripts/gazebo.material</uri>
          </script>
        </material>
      </visual>
      <visual name='end_effector_link_fixed_joint_lump__camera_holder_visual_1'>
        <pose>-0.0425 -0.0425 0.1095 -0 -0 -0.0008</pose>
        <geometry>
          <mesh>
            <scale>0.001 0.001 0.001</scale>
            <uri>model://owl_description/meshes/holder/Camera_Ur5e_gripper_Mount_Disc.STL</uri>
          </mesh>
        </geometry>
      </visual>
      <visual name='end_effector_link_fixed_joint_lump__camera_link_visual_2'>
        <pose>0.065044 -0.002586 0.14441 0.000796 0 1.57</pose>
        <geometry>
          <mesh>
            <scale>1 1 1</scale>
            <uri>model://owl_description/meshes/d435/d435.dae</uri>
          </mesh>
        </geometry>
      </visual>
      <visual name='end_effector_link_fixed_joint_lump__gripper_robotiq_arg2f_base_link_visual_3'>
        <pose>0 -0 0.1145 0 -0 3.14159</pose>
        <geometry>
          <mesh>
            <scale>0.001 0.001 0.001</scale>
            <uri>model://robotiq_2f_85_gripper_visualization/meshes/visual/robotiq_arg2f_85_base_link.dae</uri>
          </mesh>
        </geometry>
      </visual>
      <self_collide>1</self_collide>
      <self_collide>0</self_collide>
      <enable_wind>0</enable_wind>
      <kinematic>0</kinematic>
      <sensor name='cameracolor' type='camera'>
        <camera name='camera'>
          <horizontal_fov>1.21126</horizontal_fov>
          <image>
            <width>640</width>
            <height>480</height>
            <format>RGB_INT8</format>
          </image>
          <clip>
            <near>0.1</near>
            <far>100</far>
          </clip>
          <noise>
            <type>gaussian</type>
            <mean>0</mean>
            <stddev>0.007</stddev>
          </noise>
        </camera>
        <always_on>1</always_on>
        <update_rate>30</update_rate>
        <visualize>1</visualize>
        <pose>0.065046 0.014914 0.12951 -3.14159 -1.57079 3.14079</pose>
      </sensor>
      <sensor name='cameraired1' type='camera'>
        <camera name='camera'>
          <horizontal_fov>1.48702</horizontal_fov>
          <image>
            <width>1280</width>
            <height>720</height>
            <format>L_INT8</format>
          </image>
          <clip>
            <near>0.1</near>
            <far>100</far>
          </clip>
          <noise>
            <type>gaussian</type>
            <mean>0</mean>
            <stddev>0.05</stddev>
          </noise>
        </camera>
        <always_on>1</always_on>
        <update_rate>90</update_rate>
        <visualize>0</visualize>
        <pose>0.065046 0.014914 0.12951 -3.14159 -1.57079 3.14079</pose>
      </sensor>
      <sensor name='cameraired2' type='camera'>
        <camera name='camera'>
          <horizontal_fov>1.48702</horizontal_fov>
          <image>
            <width>1280</width>
            <height>720</height>
            <format>L_INT8</format>
          </image>
          <clip>
            <near>0.1</near>
            <far>100</far>
          </clip>
          <noise>
            <type>gaussian</type>
            <mean>0</mean>
            <stddev>0.05</stddev>
          </noise>
        </camera>
        <always_on>1</always_on>
        <update_rate>90</update_rate>
        <visualize>0</visualize>
        <pose>0.065046 0.014914 0.12951 -3.14159 -1.57079 3.14079</pose>
      </sensor>
      <sensor name='cameradepth' type='depth'>
        <camera name='camera'>
          <horizontal_fov>1.48702</horizontal_fov>
          <image>
            <width>1280</width>
            <height>720</height>
          </image>
          <clip>
            <near>0.1</near>
            <far>100</far>
          </clip>
          <noise>
            <type>gaussian</type>
            <mean>0</mean>
            <stddev>0.1</stddev>
          </noise>
        </camera>
        <always_on>1</always_on>
        <update_rate>90</update_rate>
        <visualize>0</visualize>
        <pose>0.065046 0.014914 0.12951 -3.14159 -1.57079 3.14079</pose>
      </sensor>
      <gravity>0</gravity>
      <gravity>0</gravity>
    </link>
    <plugin name='gazebo_ros_control' filename='libgazebo_ros_control.so'/>
    <plugin name='joint_state_publisher' filename='libgazebo_ros_joint_state_publisher.so'>
      <jointName>BJ, SJ, EJ, W1J, W2J, W3J</jointName>
    </plugin>
    <plugin name='gazebo_grasp_fix' filename='libgazebo_grasp_fix.so'>
      <arm>
        <arm_name>owl_d435</arm_name>
        <palm_link>end_effector_link</palm_link>
        <gripper_link>tcp</gripper_link>
      </arm>
      <forces_angle_tolerance>100</forces_angle_tolerance>
      <update_rate>4</update_rate>
      <grip_count_threshold>4</grip_count_threshold>
      <max_grip_count>8</max_grip_count>
      <release_tolerance>0.003</release_tolerance>
      <disable_collisions_on_attach>0</disable_collisions_on_attach>
      <contact_topic>__default_topic__</contact_topic>
    </plugin>
    <static>0</static>
    <plugin name='camera' filename='librealsense_gazebo_plugin.so'>
      <prefix>camera</prefix>
      <depthUpdateRate>30.0</depthUpdateRate>
      <colorUpdateRate>30.0</colorUpdateRate>
      <infraredUpdateRate>30.0</infraredUpdateRate>
      <depthTopicName>depth/image_raw</depthTopicName>
      <depthCameraInfoTopicName>depth/camera_info</depthCameraInfoTopicName>
      <colorTopicName>color/image_raw</colorTopicName>
      <colorCameraInfoTopicName>color/camera_info</colorCameraInfoTopicName>
      <infrared1TopicName>infra1/image_raw</infrared1TopicName>
      <infrared1CameraInfoTopicName>infra1/camera_info</infrared1CameraInfoTopicName>
      <infrared2TopicName>infra2/image_raw</infrared2TopicName>
      <infrared2CameraInfoTopicName>infra2/camera_info</infrared2CameraInfoTopicName>
      <colorOpticalframeName>camera_color_optical_frame</colorOpticalframeName>
      <depthOpticalframeName>camera_depth_optical_frame</depthOpticalframeName>
      <infrared1OpticalframeName>camera_left_ir_optical_frame</infrared1OpticalframeName>
      <infrared2OpticalframeName>camera_right_ir_optical_frame</infrared2OpticalframeName>
      <rangeMinDepth>0.2</rangeMinDepth>
      <rangeMaxDepth>1.0</rangeMaxDepth>
      <pointCloud>1</pointCloud>
      <pointCloudTopicName>depth/color/points</pointCloudTopicName>
      <pointCloudCutoff>0.25</pointCloudCutoff>
      <pointCloudCutoffMax>1.5</pointCloudCutoffMax>
    </plugin>
  </model>
</sdf>
